Workbook

Sheet Mode d'emploi
A1: Grille d'audit SaaS + IA
A2: Cadre réutilisable pour auditer n'importe quel SaaS qui intègre de l'IA.
A4: Méthode
B5: • Chaque onglet = un thème de l'audit (12 thèmes).
B6: • Score : OK / KO / N/A (dropdown sur la colonne Score).
B7: • La feuille 'Synthèse' agrège automatiquement les scores.
A9: Légende criticité
A10: 🔴 | B10: Bloquant launch — fixer avant ouverture publique
A11: 🟡 | B11: Important — à corriger sous 30 jours
A12: 🟢 | B12: Amélioration continue — nice to have
A14: Seuils de décision
A15: > 90% | B15: Ready to scale — focus growth
A16: 80-90% | B16: Ready to launch — fix les 🟡 sous 30j
A17: 65-80% | B17: Ready bêta privée — fix tous les 🔴
A18: < 65% | B18: Pas prêt pour la prod
A20: Ordre d'attaque
A21: 1. | B21: Tous les 🔴 d'abord (bloquants)
A22: 2. | B22: Légal + Données (risque pénal / régulateur)
A23: 3. | B23: Sécurité (risque incident)
A24: 4. | B24: IA Coûts + Gouvernance (risque facture / image)
A25: 5. | B25: Le reste : amélioration continue

Sheet Synthèse
A1: Synthèse de l'audit
A2: Scores agrégés par thème. Le score = (OK) / (OK + KO) — les N/A et les vides ne comptent pas.
A4: # | B4: Thème | C4: 🔴 Bloquants | D4: 🟡 Important | E4: 🟢 Polish | F4: OK | G4: KO | H4: N/A | I4: Score %
A5: 1 | B5: 1. Produit & UX | C5: =COUNTIF('01_Produit_UX'!$E$5:$E$200,"🔴") | D5: =COUNTIF('01_Produit_UX'!$E$5:$E$200,"🟡") | E5: =COUNTIF('01_Produit_UX'!$E$5:$E$200,"🟢") | F5: =COUNTIF('01_Produit_UX'!$G$5:$G$200,"OK") | G5: =COUNTIF('01_Produit_UX'!$G$5:$G$200,"KO") | H5: =COUNTIF('01_Produit_UX'!$G$5:$G$200,"N/A") | I5: =IF((F5+G5)=0,"",F5/(F5+G5))
A6: 2 | B6: 2. Sécurité & Auth | C6: =COUNTIF('02_Securite_Auth'!$E$5:$E$200,"🔴") | D6: =COUNTIF('02_Securite_Auth'!$E$5:$E$200,"🟡") | E6: =COUNTIF('02_Securite_Auth'!$E$5:$E$200,"🟢") | F6: =COUNTIF('02_Securite_Auth'!$G$5:$G$200,"OK") | G6: =COUNTIF('02_Securite_Auth'!$G$5:$G$200,"KO") | H6: =COUNTIF('02_Securite_Auth'!$G$5:$G$200,"N/A") | I6: =IF((F6+G6)=0,"",F6/(F6+G6))
A7: 3 | B7: 3. Données & Confidentialité | C7: =COUNTIF('03_Donnees_Confidentialite'!$E$5:$E$200,"🔴") | D7: =COUNTIF('03_Donnees_Confidentialite'!$E$5:$E$200,"🟡") | E7: =COUNTIF('03_Donnees_Confidentialite'!$E$5:$E$200,"🟢") | F7: =COUNTIF('03_Donnees_Confidentialite'!$G$5:$G$200,"OK") | G7: =COUNTIF('03_Donnees_Confidentialite'!$G$5:$G$200,"KO") | H7: =COUNTIF('03_Donnees_Confidentialite'!$G$5:$G$200,"N/A") | I7: =IF((F7+G7)=0,"",F7/(F7+G7))
A8: 4 | B8: 4. IA — Pertinence & Qualité | C8: =COUNTIF('04_IA_Qualite'!$E$5:$E$200,"🔴") | D8: =COUNTIF('04_IA_Qualite'!$E$5:$E$200,"🟡") | E8: =COUNTIF('04_IA_Qualite'!$E$5:$E$200,"🟢") | F8: =COUNTIF('04_IA_Qualite'!$G$5:$G$200,"OK") | G8: =COUNTIF('04_IA_Qualite'!$G$5:$G$200,"KO") | H8: =COUNTIF('04_IA_Qualite'!$G$5:$G$200,"N/A") | I8: =IF((F8+G8)=0,"",F8/(F8+G8))
A9: 5 | B9: 5. IA — Coûts & Limites | C9: =COUNTIF('05_IA_Couts'!$E$5:$E$200,"🔴") | D9: =COUNTIF('05_IA_Couts'!$E$5:$E$200,"🟡") | E9: =COUNTIF('05_IA_Couts'!$E$5:$E$200,"🟢") | F9: =COUNTIF('05_IA_Couts'!$G$5:$G$200,"OK") | G9: =COUNTIF('05_IA_Couts'!$G$5:$G$200,"KO") | H9: =COUNTIF('05_IA_Couts'!$G$5:$G$200,"N/A") | I9: =IF((F9+G9)=0,"",F9/(F9+G9))
A10: 6 | B10: 6. IA — Gouvernance & cadre légal | C10: =COUNTIF('06_IA_Gouvernance'!$E$5:$E$200,"🔴") | D10: =COUNTIF('06_IA_Gouvernance'!$E$5:$E$200,"🟡") | E10: =COUNTIF('06_IA_Gouvernance'!$E$5:$E$200,"🟢") | F10: =COUNTIF('06_IA_Gouvernance'!$G$5:$G$200,"OK") | G10: =COUNTIF('06_IA_Gouvernance'!$G$5:$G$200,"KO") | H10: =COUNTIF('06_IA_Gouvernance'!$G$5:$G$200,"N/A") | I10: =IF((F10+G10)=0,"",F10/(F10+G10))
A11: 7 | B11: 7. Architecture & Scalabilité | C11: =COUNTIF('07_Architecture'!$E$5:$E$200,"🔴") | D11: =COUNTIF('07_Architecture'!$E$5:$E$200,"🟡") | E11: =COUNTIF('07_Architecture'!$E$5:$E$200,"🟢") | F11: =COUNTIF('07_Architecture'!$G$5:$G$200,"OK") | G11: =COUNTIF('07_Architecture'!$G$5:$G$200,"KO") | H11: =COUNTIF('07_Architecture'!$G$5:$G$200,"N/A") | I11: =IF((F11+G11)=0,"",F11/(F11+G11))
A12: 8 | B12: 8. Paiement & Monétisation | C12: =COUNTIF('08_Paiement'!$E$5:$E$200,"🔴") | D12: =COUNTIF('08_Paiement'!$E$5:$E$200,"🟡") | E12: =COUNTIF('08_Paiement'!$E$5:$E$200,"🟢") | F12: =COUNTIF('08_Paiement'!$G$5:$G$200,"OK") | G12: =COUNTIF('08_Paiement'!$G$5:$G$200,"KO") | H12: =COUNTIF('08_Paiement'!$G$5:$G$200,"N/A") | I12: =IF((F12+G12)=0,"",F12/(F12+G12))
A13: 9 | B13: 9. Observabilité & Ops | C13: =COUNTIF('09_Observabilite'!$E$5:$E$200,"🔴") | D13: =COUNTIF('09_Observabilite'!$E$5:$E$200,"🟡") | E13: =COUNTIF('09_Observabilite'!$E$5:$E$200,"🟢") | F13: =COUNTIF('09_Observabilite'!$G$5:$G$200,"OK") | G13: =COUNTIF('09_Observabilite'!$G$5:$G$200,"KO") | H13: =COUNTIF('09_Observabilite'!$G$5:$G$200,"N/A") | I13: =IF((F13+G13)=0,"",F13/(F13+G13))
A14: 10 | B14: 10. Légal & Conformité | C14: =COUNTIF('10_Legal'!$E$5:$E$200,"🔴") | D14: =COUNTIF('10_Legal'!$E$5:$E$200,"🟡") | E14: =COUNTIF('10_Legal'!$E$5:$E$200,"🟢") | F14: =COUNTIF('10_Legal'!$G$5:$G$200,"OK") | G14: =COUNTIF('10_Legal'!$G$5:$G$200,"KO") | H14: =COUNTIF('10_Legal'!$G$5:$G$200,"N/A") | I14: =IF((F14+G14)=0,"",F14/(F14+G14))
A15: 11 | B15: 11. UX/UI — Qualité de design | C15: =COUNTIF('11_UX_UI_Design'!$E$5:$E$200,"🔴") | D15: =COUNTIF('11_UX_UI_Design'!$E$5:$E$200,"🟡") | E15: =COUNTIF('11_UX_UI_Design'!$E$5:$E$200,"🟢") | F15: =COUNTIF('11_UX_UI_Design'!$G$5:$G$200,"OK") | G15: =COUNTIF('11_UX_UI_Design'!$G$5:$G$200,"KO") | H15: =COUNTIF('11_UX_UI_Design'!$G$5:$G$200,"N/A") | I15: =IF((F15+G15)=0,"",F15/(F15+G15))
A16: 12 | B16: 12. Frontend ↔ Backend | C16: =COUNTIF('12_Frontend_Backend'!$E$5:$E$200,"🔴") | D16: =COUNTIF('12_Frontend_Backend'!$E$5:$E$200,"🟡") | E16: =COUNTIF('12_Frontend_Backend'!$E$5:$E$200,"🟢") | F16: =COUNTIF('12_Frontend_Backend'!$G$5:$G$200,"OK") | G16: =COUNTIF('12_Frontend_Backend'!$G$5:$G$200,"KO") | H16: =COUNTIF('12_Frontend_Backend'!$G$5:$G$200,"N/A") | I16: =IF((F16+G16)=0,"",F16/(F16+G16))
A17: 13 | B17: 13. Documentation & Maintenance | C17: =COUNTIF('13_Documentation_Maintenance'!$E$5:$E$200,"🔴") | D17: =COUNTIF('13_Documentation_Maintenance'!$E$5:$E$200,"🟡") | E17: =COUNTIF('13_Documentation_Maintenance'!$E$5:$E$200,"🟢") | F17: =COUNTIF('13_Documentation_Maintenance'!$G$5:$G$200,"OK") | G17: =COUNTIF('13_Documentation_Maintenance'!$G$5:$G$200,"KO") | H17: =COUNTIF('13_Documentation_Maintenance'!$G$5:$G$200,"N/A") | I17: =IF((F17+G17)=0,"",F17/(F17+G17))
B18: TOTAL | C18: =SUM(C5:C17) | D18: =SUM(D5:D17) | E18: =SUM(E5:E17) | F18: =SUM(F5:F17) | G18: =SUM(G5:G17) | H18: =SUM(H5:H17) | I18: =IF((F18+G18)=0,"",F18/(F18+G18))
B21: Seuils
B22: > 90% | C22: Ready to scale — focus growth
B23: 80-90% | C23: Ready to launch — fix 🟡 sous 30j
B24: 65-80% | C24: Ready bêta — fix tous les 🔴
B25: < 65% | C25: Pas prêt pour la prod

Sheet 01_Produit_UX
A1: 1. Produit & UX
A2: Friction first-run, empty states, accessibilité de base, mobile, social meta.
A4: # | B4: Question Chef de Projet | C4: Critère Développeur | D4: Comment tester | E4: Crit. | F4: Auto | G4: Score | H4: Commentaire | I4: Outils & IA
A5: 1.1 | B5: Un nouvel utilisateur comprend-il l'intérêt du produit en moins d'une minute ? | C5: First-time user voit la valeur en < 60 sec | D5: Inscription incognito → chrono jusqu'au 'wow moment' | E5: 🔴 | F5: 👤 | H5: ⚠️ Test utilisateur réel obligatoire — l'automatisation ne mesure pas la compréhension | I5: 🔧 Hotjar · Maze · FullStory (freemium) 🤖 Claude : revue du parcours signup → first action. Prompt : 'Identifie les frictions sur ce parcours d'onboarding'
A6: 1.2 | B6: Un compte vierge propose-t-il à l'utilisateur quoi faire en premier ? | C6: Empty state du dashboard guide l'action (pas un trou) | D6: Compte vierge → présence de cards onboarding ou CTA primaire | E6: 🟡 | F6: 🔁 | I6: 🔧 Playwright (gratuit) · Storybook (gratuit) 🤖 Claude : audit visuel de l'empty state sur capture
A7: 1.3 | B7: Les boutons disent-ils clairement ce qu'ils déclenchent ? | C7: Tous les CTA disent ce qu'ils font (pas de 'Valider' ambigu) | D7: Parcours tous les boutons → label = action backend ? | E7: 🟡 | F7: 🔁 | I7: 🔧 grep / ripgrep sur les `<button>` (gratuit) 🤖 Claude : revue des labels de CTA dans le code source
A8: 1.4 | B8: Quand quelque chose plante, l'utilisateur sait-il ce qui se passe et comment continuer ? | C8: Erreurs réseau/API toastent un message utilisable | D8: Couper le réseau → tester save/upload/login | E8: 🟡 | F8: 🔁 | I8: 🔧 Playwright avec route mocking (gratuit) · Sentry (freemium) 🤖 Claude : audit des handlers d'erreur dans le code
A9: 1.5 | B9: L'utilisateur sait-il toujours quand quelque chose est en train de charger ? | C9: Loading states partout (skeletons, spinners) — pas de freeze visuel | D9: Throttle réseau à Slow 3G → vérifier feedback | E9: 🟢 | F9: 🔁 | I9: 🔧 DevTools network throttling (gratuit) · Lighthouse (gratuit)
A10: 1.6 | B10: L'application est-elle utilisable confortablement sur un téléphone d'entrée de gamme ? | C10: Mobile responsive testé sur le plus petit viewport ciblé | D10: DevTools mode iPhone SE (375px) ou équivalent | E10: 🔴 | F10: 🔁 | H10: ⚠️ Test sur appareil réel recommandé pour le tactile | I10: 🔧 Playwright multi-viewport (gratuit) · BrowserStack (payant) 🤖 Claude : revue des breakpoints CSS et media queries
A11: 1.7 | B11: Quelqu'un sans souris peut-il utiliser l'application ? | C11: Tab navigation (clavier seul) fonctionne sur tous les formulaires | D11: Tab/Shift+Tab → focus visible et logique | E11: 🟡 | F11: 🔁 | H11: ⚠️ Test clavier réel humain irremplaçable | I11: 🔧 axe DevTools (gratuit) · Lighthouse a11y (gratuit) 🤖 Claude : audit du tabindex et des focus rings
A12: 1.8 | B12: Reste-t-il des textes de test ou des placeholders dans l'app ? | C12: Pas de Lorem ipsum, placeholders TODO, ou textes oubliés dans une autre langue | D12: grep `lorem`, `todo`, `tbd`, `xxx` dans le code | E12: 🔴 | F12: 🤖 | I12: 🔧 ripgrep / ESLint custom rule (gratuit) 🤖 Claude : scan du code pour textes suspects (faux positifs filtrés par contexte)
A13: 1.9 | B13: Si l'app affiche 5 langues, sont-elles toutes complètes ? | C13: i18n cohérent : tous les libellés visibles sont traduits dans toutes les langues annoncées | D13: Switch toutes les langues → screen audit | E13: 🟡 | F13: 🔁 | H13: ⚠️ Traduction humaine recommandée pour les marchés clés | I13: 🔧 i18next-parser (gratuit) · Lokalise (payant) 🤖 Claude : traduction et adaptation culturelle des contenus + détection de clés manquantes
A14: 1.10 | B14: Un utilisateur peut-il supprimer son compte ou un projet par erreur en un clic ? | C14: Confirmation pour actions destructives (suppression, paiement, opt-out) | D14: Tester chaque suppression — modal de confirmation présent ? | E14: 🔴 | F14: 🔁 | I14: 🔧 Playwright tests parcours destructifs (gratuit) 🤖 Claude : grep des onClick.*delete|remove|destroy sans modal
A15: 1.11 | B15: Les textes sont-ils lisibles pour quelqu'un avec une vision faible ? | C15: Contraste WCAG AA minimum sur les textes (4.5:1 normal, 3:1 large) | D15: Lighthouse accessibility audit | E15: 🟡 | F15: 🤖 | I15: 🔧 Lighthouse (gratuit) · WebAIM Contrast Checker (gratuit) · Stark (freemium)
A16: 1.12 | B16: Quand une page est partagée sur LinkedIn/Twitter, l'aperçu donne envie de cliquer ? | C16: Open Graph et Twitter Cards configurés sur les pages partageables | D16: Inspecter <head> → og:title, og:description, og:image présents + dimensions correctes | E16: 🟢 | F16: 🤖 | I16: 🔧 Lighthouse SEO (gratuit) · OpenGraph.xyz (gratuit)
A17: 1.13 | B17: L'application marche-t-elle sur tous les navigateurs courants, pas que Chrome ? | C17: Compatibilité cross-browser testée (Chrome, Firefox, Safari, Edge) | D17: Playwright en mode multi-browser ou test manuel sur les 4 | E17: 🟡 | F17: 🤖 | H17: ⚠️ Safari en particulier a des comportements WebKit propres — test réel recommandé | I17: 🔧 Playwright cross-browser (gratuit) · BrowserStack (payant pour Safari/IE legacy)

Sheet 02_Securite_Auth
A1: 2. Sécurité & Auth
A2: Tokens, CSP, 2FA, rate-limit, hash, secrets, headers, validation, audit.
A4: # | B4: Question Chef de Projet | C4: Critère Développeur | D4: Comment tester | E4: Crit. | F4: Auto | G4: Score | H4: Commentaire | I4: Outils & IA
A5: 2.1 | B5: Le token de connexion est-il à l'abri d'un script malveillant ? | C5: Sessions via cookie httpOnly + Secure + SameSite Lax/Strict (pas token en localStorage seul) | D5: DevTools → Application → Cookies | E5: 🔴 | F5: 🤖 | I5: 🔧 DevTools (gratuit) · securityheaders.com (gratuit) 🤖 Claude : revue du code d'auth pour vérifier les flags du cookie
A6: 2.2 | B6: Le site est-il protégé contre l'injection de scripts malveillants ? | C6: CSP en production avec script-src/connect-src restreints (pas de 'unsafe-inline' sur script-src) | D6: Inspecter le header Content-Security-Policy | E6: 🔴 | F6: 🤖 | I6: 🔧 securityheaders.com (gratuit) · CSP Evaluator Google (gratuit) 🤖 Claude : audit de la CSP et identification des directives manquantes
A7: 2.3 | B7: Les comptes sensibles (admin, finance) ont-ils une double authentification ? | C7: 2FA disponible pour tous, obligatoire pour les comptes admin / privilégiés | D7: Désactiver 2FA admin → l'app doit refuser l'accès aux endpoints sensibles | E7: 🔴 | F7: 🔁 | I7: 🔧 Playwright tests flow 2FA (gratuit) 🤖 Claude : revue du middleware admin pour vérifier l'enforcement 2FA
A8: 2.4 | B8: Le site est-il protégé contre les attaques de force brute sur les mots de passe ? | C8: Rate limit sur les endpoints d'auth (/login, /register, /password/reset) | D8: Stresser avec curl → 429 doit apparaître après N tentatives | E8: 🔴 | F8: 🤖 | I8: 🔧 k6 (gratuit) · Artillery (gratuit) · curl loops (gratuit) 🤖 Claude : audit des middlewares de rate-limiting sur les routes sensibles
A9: 2.5 | B9: Les mots de passe sont-ils stockés de façon irréversible ? | C9: Hash mot de passe bcrypt (cost ≥ 10) ou argon2 ou scrypt | D9: Inspecter le code de signup/auth | E9: 🔴 | F9: 🤖 | I9: 🔧 Semgrep règles password hashing (gratuit) 🤖 Claude : revue du code de hashing — détection de MD5/SHA1/plain
A10: 2.6 | B10: Un attaquant peut-il savoir si un email a un compte chez vous ? | C10: Anti-énumération sur login (même message pour email inexistant vs mot de passe faux) | D10: Tenter login email connu vs inconnu | E10: 🟡 | F10: 🔁 | I10: 🔧 curl / Postman (gratuit) 🤖 Claude : revue des handlers de login pour détecter des messages d'erreur révélateurs
A11: 2.7 | B11: Un utilisateur sans email vérifié peut-il payer ou exporter des données ? | C11: Email verification obligatoire avant accès aux features sensibles | D11: Compte non vérifié → essayer payer, exporter | E11: 🟡 | F11: 🔁 | I11: 🔧 Playwright tests flow signup (gratuit)
A12: 2.8 | B12: Si on retire les droits d'un admin, perd-il l'accès immédiatement ? | C12: Authorization vérifie le rôle contre la DB (pas seulement le claim JWT/session) | D12: Demoter un admin en DB → son token doit perdre accès dans la minute | E12: 🟡 | F12: 🔁 | I12: 🔧 Test manuel + Playwright (gratuit) 🤖 Claude : audit du middleware d'autorisation
A13: 2.9 | B13: Y a-t-il des clés API ou mots de passe accidentellement commités dans le code ? | C13: Aucun secret en clair dans le repo (clés API, mots de passe, tokens) | D13: git log -p + scan secrets | E13: 🔴 | F13: 🤖 | H13: ⚠️ Scan historique git complet recommandé — un secret retiré peut traîner dans l'historique | I13: 🔧 GitGuardian (freemium) · Trufflehog (gratuit) · Gitleaks (gratuit) · git secrets (gratuit) 🤖 Claude : scan ciblé sur les patterns suspects (sk_live_*, key-*, etc.)
A14: 2.10 | B14: Le site déploie-t-il les protections HTTP standards contre le clickjacking et l'écoute ? | C14: Headers de sécurité : X-Frame-Options, HSTS, Referrer-Policy, Permissions-Policy | D14: Tester via securityheaders.com → grade ≥ A | E14: 🟡 | F14: 🤖 | I14: 🔧 securityheaders.com (gratuit) · Mozilla Observatory (gratuit)
A15: 2.11 | B15: Le serveur vérifie-t-il toutes les données reçues, ou fait-il confiance au frontend ? | C15: Validation côté serveur (Zod / Joi / Pydantic / équivalent) sur toutes les routes mutantes | D15: Auditer chaque route POST/PUT/PATCH/DELETE | E15: 🔴 | F15: 🔁 | H15: ⚠️ Les règles métier complexes nécessitent validation humaine | I15: 🔧 Semgrep (gratuit) · revue manuelle 🤖 Claude : audit route par route pour vérifier la présence d'un schema de validation
A16: 2.12 | B16: Une page tierce peut-elle déclencher une action au nom de l'utilisateur ? | C16: Protection CSRF active sur les requêtes mutantes en cookie-auth | D16: Tester soumission cross-origin sans token | E16: 🟡 | F16: 🔁 | I16: 🔧 OWASP ZAP (gratuit) · Burp Suite (freemium) 🤖 Claude : audit de la config CSRF et SameSite
A17: 2.13 | B17: En cas d'incident, peut-on tracer qui a fait quoi côté admin ? | C17: Logs d'audit pour actions admin sensibles (création/suppression user, role change, payout) | D17: Existence d'une table d'audit + accessibilité | E17: 🟡 | F17: 🔁 | I17: 🔧 grep sur les actions sensibles · revue de schema DB 🤖 Claude : audit des handlers admin pour vérifier la présence de logAdminAction()
A18: 2.14 | B18: Les librairies tierces sont-elles à jour côté sécurité ? | C18: Dépendances scannées (npm audit / Snyk / Dependabot) — pas de CVE critique en prod | D18: Dernier rapport scan ≤ 7 jours | E18: 🟡 | F18: 🤖 | H18: ⚠️ Faux positifs fréquents — humain pour décider d'updater ou de mute | I18: 🔧 Snyk (freemium) · Dependabot (gratuit GitHub) · npm audit (gratuit) 🤖 Claude : aide à la priorisation des CVE selon l'exposition réelle

Sheet 03_Donnees_Confidentialite
A1: 3. Données & Confidentialité
A2: Droits utilisateurs, DPA, rétention, cookies, chiffrement, hébergement.
A4: # | B4: Question Chef de Projet | C4: Critère Développeur | D4: Comment tester | E4: Crit. | F4: Auto | G4: Score | H4: Commentaire | I4: Outils & IA
A5: 3.1 | B5: Un utilisateur peut-il récupérer toutes ses données dans un format utilisable ? | C5: Export des données personnelles (droit d'accès) — format machine-readable | D5: Endpoint /account/export fonctionnel | E5: 🔴 | F5: 🔁 | I5: 🔧 Playwright tests E2E (gratuit) 🤖 Claude : audit du endpoint d'export pour vérifier la complétude
A6: 3.2 | B6: Quand un utilisateur supprime son compte, ses données disparaissent-elles vraiment ? | C6: Suppression compte respecte le droit à l'oubli (anonymisation si transactions à garder) | D6: Tester delete → User row anonymisée, transactions intactes | E6: 🔴 | F6: 🔁 | H6: ⚠️ Vérification juridique requise | I6: 🔧 Test manuel + revue de schema DB 🤖 Claude : audit du flow de suppression pour vérifier l'anonymisation cross-tables
A7: 3.3 | B7: Avons-nous le registre des traitements RGPD à jour ? | C7: Registre des traitements documenté (qui traite quoi, finalité, base légale, durée) | D7: Document accessible et à jour | E7: 🔴 | F7: 👤 | H7: ⚠️ Validation juridique obligatoire | I7: 🔧 Modèle CNIL (gratuit) · Vanta / Drata (payant) 🤖 Claude : génération d'une première version du registre à partir d'une description
A8: 3.4 | B8: Tous nos prestataires qui voient des données utilisateurs ont-ils signé un contrat RGPD avec nous ? | C8: DPA signés avec tous les fournisseurs traitant des données perso | D8: Liste des sous-traitants + statut contractuel | E8: 🔴 | F8: 👤 | H8: ⚠️ Signature et conservation juridique requises | I8: 🔧 Liste sous-traitants + tracker contractuel 🤖 Claude : aide à la rédaction des questions à poser à chaque sous-traitant
A9: 3.5 | B9: Avons-nous évalué le risque RGPD pour les traitements sensibles (IA, tracking, scoring) ? | C9: Analyse d'impact (DPIA / PIA) si traitement à risque | D9: Document présent et à jour | E9: 🟡 | F9: 👤 | H9: ⚠️ Validation par DPO si nommé | I9: 🔧 Outil PIA CNIL (gratuit) 🤖 Claude : aide à la rédaction de la DPIA selon EBIOS RM
A10: 3.6 | B10: Les données européennes restent-elles en Europe ? | C10: Hébergement aligné avec les exigences de la juridiction des utilisateurs | D10: Vérifier la région des bases, buckets, providers IA | E10: 🟡 | F10: 🔁 | I10: 🔧 Audit config cloud (console) 🤖 Claude : revue des configs Terraform/CloudFormation pour localiser les ressources
A11: 3.7 | B11: Conservons-nous les données plus longtemps que nécessaire ? | C11: Politique de rétention écrite + job de purge automatique | D11: Document + job documenté et qui tourne | E11: 🔴 | F11: 🔁 | I11: 🔧 Cron / Cloud Scheduler · revue de code des jobs 🤖 Claude : audit des jobs de purge et de leurs critères
A12: 3.8 | B12: Notre bandeau cookie respecte-t-il les règles CNIL ? | C12: Bannière cookie conforme (refus = même clic qu'accepter) | D12: Inspecter en visiteur — pas de pré-cochage | E12: 🔴 | F12: 🤖 | I12: 🔧 Axeptio (freemium) · Cookiebot (freemium) · Klaro (gratuit) 🤖 Claude : audit visuel de la bannière sur capture
A13: 3.9 | B13: Aucun tracker ne se déclenche avant que l'utilisateur dise oui ? | C13: Trackers / analytics chargés UNIQUEMENT après consentement | D13: DevTools Network avant accept → aucun call GA/Meta | E13: 🔴 | F13: 🤖 | I13: 🔧 DevTools (gratuit) · Axeptio dashboard (freemium)
A14: 3.10 | B14: Pouvons-nous identifier qui a uploadé quoi sur demande judiciaire ? | C14: Logs d'identification (IP+UA+horodatage) si hébergeur de contenu | D14: Table de logs + durée de rétention conforme | E14: 🟡 | F14: 🔁 | H14: ⚠️ LCEN art. 6-II en France | I14: 🔧 Revue de schema DB 🤖 Claude : audit des points d'upload pour vérifier le logging
A15: 3.11 | B15: Avons-nous nommé un DPO et l'avons-nous communiqué ? | C15: DPO / Privacy Officer désigné si la juridiction l'exige | D15: Coordonnées affichées dans les mentions | E15: 🟡 | F15: 👤 | H15: ⚠️ Décision RH / juridique | I15: 🔧 —
A16: 3.12 | B16: Si quelqu'un volait le disque, pourrait-il lire les données ? | C16: Chiffrement at-rest activé sur la DB et les buckets | D16: Vérifier config cloud / fournisseur | E16: 🟡 | F16: 🤖 | I16: 🔧 Cloud provider audit (gratuit)
A17: 3.13 | B17: Les communications avec notre serveur sont-elles chiffrées avec un protocole moderne ? | C17: TLS 1.2 minimum sur tous les endpoints publics (idéalement TLS 1.3) | D17: SSL Labs test → grade A | E17: 🔴 | F17: 🤖 | I17: 🔧 SSL Labs (gratuit) · testssl.sh (gratuit)
A18: 3.14 | B18: Nos URLs contiennent-elles des emails ou identifiants personnels que Google pourrait indexer ? | C18: Pas de PII dans les URLs (email, ID en query string indexable) | D18: Audit des routes | E18: 🟡 | F18: 🤖 | I18: 🔧 grep / ripgrep sur le code (gratuit) 🤖 Claude : audit des routes pour détecter les query params sensibles

Sheet 04_IA_Qualite
A1: 4. IA — Pertinence & Qualité
A2: Eval set, hallucinations, prompt injection, output filtering, versioning, fallback.
A4: # | B4: Question Chef de Projet | C4: Critère Développeur | D4: Comment tester | E4: Crit. | F4: Auto | G4: Score | H4: Commentaire | I4: Outils & IA
A5: 4.1 | B5: Quand on change un prompt, sait-on objectivement si c'est mieux ou pire ? | C5: Set d'évaluation (eval set) figé pour tester les prompts à chaque changement | D5: Dossier evals/ ou framework Promptfoo/Braintrust/DeepEval/Ragas | E5: 🟡 | F5: 🤖 | H5: ⚠️ Curation des golden answers par expert métier | I5: 🔧 Promptfoo (gratuit) · Braintrust (freemium) · DeepEval (gratuit) 🤖 Claude : aide à construire le set d'eval initial (golden examples)
A6: 4.2 | B6: Mesure-t-on objectivement la qualité des sorties IA en production ? | C6: Score de pertinence mesuré sur les sorties IA (golden answers + similarity / LLM-as-judge) | D6: Process documenté + dashboard | E6: 🟢 | F6: 🔁 | H6: ⚠️ Spot-check humain recommandé | I6: 🔧 LangSmith (freemium) · Braintrust (freemium) 🤖 Claude : peut faire le LLM-as-judge sur batch de sorties
A7: 4.3 | B7: Vérifions-nous régulièrement que l'IA n'invente pas de faits ? | C7: Détection des hallucinations (output contredit input, faits inventés, citations falsifiées) | D7: Sample de 50 sorties prod → review manuel | E7: 🟡 | F7: 🔁 | I7: 🔧 Échantillonnage manuel · LLM-as-judge 🤖 Claude : peut comparer output vs sources pour détecter les inventions
A8: 4.4 | B8: Un utilisateur malveillant peut-il faire dire n'importe quoi à notre IA ? | C8: Prompt injection testé (user input contient 'ignore instructions above', roleplay) | D8: 10 inputs hostiles → mesurer escape rate | E8: 🔴 | F8: 🤖 | I8: 🔧 Promptfoo (gratuit) · Garak (gratuit) 🤖 Claude : génération de payloads adversariaux pour tester
A9: 4.5 | B9: Notre IA peut-elle générer du contenu illégal ou dangereux ? | C9: Output filtré pour contenu prohibé (NSFW, instructions dangereuses, contenu illégal) | D9: Prompts adversariaux → contenu bloqué ? | E9: 🔴 | F9: 🤖 | I9: 🔧 Vertex AI safety filters (inclus) · OpenAI moderation API (gratuit) · Lakera Guard (payant)
A10: 4.6 | B10: Peut-on revenir en arrière sur un changement de prompt qui dégrade la qualité ? | C10: Versioning des prompts (commit dans le code, pas hardcodé inline) | D10: Prompts dans des fichiers dédiés versionnés ? | E10: 🟡 | F10: 🤖 | I10: 🔧 git + dossier prompts/ dédié 🤖 Claude : refactor des prompts inline vers fichiers dédiés
A11: 4.7 | B11: Si le fournisseur change le modèle silencieusement, notre app le sait ? | C11: Versioning du modèle (référence à une version pinnée, pas 'latest') | D11: Inspecter l'appel SDK | E11: 🟡 | F11: 🤖 | I11: 🔧 grep sur les appels SDK IA (gratuit) 🤖 Claude : détection des appels modèle non-pinned
A12: 4.8 | B12: Que se passe-t-il si le fournisseur d'IA est en panne ? | C12: Fallback déterministe quand l'IA échoue (rate limit, model down, output unparseable) | D12: Couper la clé API → mode dégradé propre ? | E12: 🔴 | F12: 🔁 | I12: 🔧 Test manuel : modifier la clé API · chaos engineering 🤖 Claude : revue des handlers d'erreur IA
A13: 4.9 | B13: Si l'IA renvoie un format inattendu, l'app crash ou récupère ? | C13: Validation des outputs structurés (JSON schema/Pydantic/Zod) avec retry si malformé | D13: Inspecter post-traitement IA | E13: 🟡 | F13: 🔁 | I13: 🔧 Zod / Pydantic (gratuit) 🤖 Claude : audit du post-traitement IA pour identifier les unsafe parses
A14: 4.10 | B14: L'utilisateur sait-il toujours quand un contenu vient de l'IA ? | C14: Disclaimer 'Généré par IA, peut contenir des erreurs' visible sur chaque sortie | D14: Audit visuel des écrans avec output IA | E14: 🟡 | F14: 🔁 | I14: 🔧 Capture + audit visuel
A15: 4.11 | B15: L'utilisateur peut-il vérifier sur quelle source l'IA s'est basée ? | C15: Citation/source affichée si l'IA fait du RAG sur des documents internes | D15: UI montre les passages utilisés ? | E15: 🟢 | F15: 🔁 | I15: 🔧 Audit UX (gratuit)

Sheet 05_IA_Couts
A1: 5. IA — Coûts & Limites
A2: Quota utilisateur, suivi coûts, alertes, max tokens, rate limit, cache, fallback, idempotency.
A4: # | B4: Question Chef de Projet | C4: Critère Développeur | D4: Comment tester | E4: Crit. | F4: Auto | G4: Score | H4: Commentaire | I4: Outils & IA
A5: 5.1 | B5: Un utilisateur peut-il consommer 10 000 € d'IA en quelques minutes ? | C5: Quota par utilisateur (crédits IA, calls/mois) avec compteur en DB | D5: Tester épuisement → 402 / blocage propre | E5: 🔴 | F5: 🔁 | I5: 🔧 Test manuel + revue de schema DB 🤖 Claude : audit du middleware de quota IA
A6: 5.2 | B6: Savons-nous combien coûte chaque utilisateur en IA ? | C6: Coût par appel suivi et journalisé (tokens in/out × tarif modèle) | D6: Table d'usage IA ou métriques équivalentes | E6: 🟡 | F6: 🔁 | I6: 🔧 Helicone (freemium) · LangSmith (freemium) 🤖 Claude : aide à l'instrumentation du logging coût
A7: 5.3 | B7: Recevons-nous une alerte si la facture IA explose ? | C7: Budget global plateforme avec alerte automatique (quotidien + mensuel) | D7: Budget configuré côté fournisseur cloud + IA | E7: 🔴 | F7: 🤖 | I7: 🔧 GCP / AWS / Azure Billing Alerts (gratuit) · OpenAI usage limits (gratuit)
A8: 5.4 | B8: Un utilisateur peut-il envoyer un livre entier dans le prompt ? | C8: Limite max de tokens par requête (anti coût explosif) | D8: Input de 100 000 caractères → refusé avant appel IA ? | E8: 🔴 | F8: 🤖 | I8: 🔧 tiktoken (gratuit) · audit code 🤖 Claude : audit des appels IA pour vérifier la troncature inputs
A9: 5.5 | B9: Si quelqu'un spamme l'IA, ça nous coûte beaucoup ou ça plante ? | C9: Rate limit / file d'attente sur les calls IA (anti-DDoS coûteux) | D9: Burst 100 calls/sec → 429 ou queue ? | E9: 🟡 | F9: 🤖 | I9: 🔧 k6 (gratuit) · curl loop
A10: 5.6 | B10: Si 100 utilisateurs posent la même question, payons-nous 100 fois ? | C10: Cache des prompts répétés (même input → sortie servie depuis cache) | D10: 2× la même requête → 2nd appel < 100ms | E10: 🟢 | F10: 🔁 | I10: 🔧 Anthropic prompt caching (inclus) · Redis cache custom 🤖 Claude : aide à la stratégie de cache (TTL, clés)
A11: 5.7 | B11: Utilise-t-on le modèle le moins cher capable de faire le travail ? | C11: Modèle moins cher en fallback automatique sur les tâches simples | D11: Documentation du routing | E11: 🟢 | F11: 🔁 | I11: 🔧 Audit code des appels modèle 🤖 Claude : aide à classer les tâches par complexité requise
A12: 5.8 | B12: Si l'IA met 5 minutes à répondre, l'app reste-t-elle bloquée ? | C12: Timeout sur l'appel modèle (≤ 30s) | D12: Inspecter le code SDK + tester sur prompt lent | E12: 🟡 | F12: 🤖 | I12: 🔧 grep sur les options SDK timeout
A13: 5.9 | B13: Les utilisateurs gratuits ont-ils une limite claire de consommation IA ? | C13: Free tier limité : signup bonus, pas un quota infini | D13: Compte free → quota visible et opposable | E13: 🟡 | F13: 🔁 | I13: 🔧 Test manuel signup → consommation
A14: 5.10 | B14: Un retry technique fait-il payer deux fois l'utilisateur ? | C14: Idempotency sur les calls IA payés (retry réseau ne re-débite pas) | D14: Tester double-call avec idem-key | E14: 🟡 | F14: 🔁 | I14: 🔧 Test manuel · revue code 🤖 Claude : audit des appels IA débités pour vérifier l'idempotency-key
A15: 5.11 | B15: L'utilisateur voit-il la réponse arriver progressivement, ou attend-il un bloc ? | C15: Streaming activé pour les réponses longues (réduit perceived latency) | D15: Calls retournent en SSE/chunks ? | E15: 🟢 | F15: 🔁 | I15: 🔧 DevTools Network (gratuit)

Sheet 06_IA_Gouvernance
A1: 6. IA — Gouvernance & cadre légal
A2: Transparence, classification AI Act, opt-out training, watermarking, model cards, audit-trail.
A4: # | B4: Question Chef de Projet | C4: Critère Développeur | D4: Comment tester | E4: Crit. | F4: Auto | G4: Score | H4: Commentaire | I4: Outils & IA
A5: 6.1 | B5: Les utilisateurs savent-ils quelle IA on utilise et pourquoi ? | C5: Modèle(s) utilisé(s) + finalité divulgué(s) dans CGU + politique de confidentialité | D5: Section IA explicite ? | E5: 🔴 | F5: 👤 | H5: ⚠️ Validation juridique | I5: 🔧 — 🤖 Claude : rédaction de la section IA dans les CGU et privacy policy
A6: 6.2 | B6: L'utilisateur consent-il avant qu'une IA prenne une décision le concernant ? | C6: Consentement explicite si l'IA prend une décision impactante | D6: UI de consentement avant feature IA-décisionnelle | E6: 🟡 | F6: 🔁 | H6: ⚠️ AI Act art. 14 | I6: 🔧 Audit UX (gratuit)
A7: 6.3 | B7: Avons-nous classé notre IA selon le AI Act européen ? | C7: Classification du système IA selon le cadre applicable (ex. EU AI Act) | D7: Classification documentée + actions selon catégorie | E7: 🟡 | F7: 👤 | H7: ⚠️ Décision juridique | I7: 🔧 Modèle d'auto-évaluation Commission UE 🤖 Claude : aide à la classification + checklist obligations selon catégorie
A8: 6.4 | B8: L'utilisateur peut-il refuser que ses données servent à entraîner l'IA ? | C8: Opt-out fourniture de données pour entraînement | D8: Setting utilisateur 'Ne pas utiliser mes données' | E8: 🟡 | F8: 🔁 | I8: 🔧 Audit UX (gratuit)
A9: 6.5 | B9: Si on génère des images ou vidéos, sont-elles identifiables comme IA ? | C9: Watermarking / disclosure si output confondable avec contenu humain (deepfake) | D9: UI/metadata signalent l'origine IA | E9: 🟢 | F9: 🔁 | H9: ⚠️ AI Act art. 50 | I9: 🔧 SynthID (gratuit Google) · C2PA standards
A10: 6.6 | B10: Le fournisseur d'IA est-il dans notre registre des sous-traitants RGPD ? | C10: Provider IA déclaré comme sous-traitant dans le registre (DPA signé) | D10: Registre à jour | E10: 🔴 | F10: 👤 | I10: 🔧 Registre des sous-traitants
A11: 6.7 | B11: Avons-nous documenté ce que l'IA sait faire et ce qu'elle ne sait pas faire ? | C11: Model card disponible (description, biais connus, limitations) | D11: Document accessible aux utilisateurs business | E11: 🟢 | F11: 👤 | I11: 🔧 Modèle Hugging Face model card 🤖 Claude : rédaction de la model card à partir d'une description du système
A12: 6.8 | B12: Une décision importante (refus, suspension) est-elle prise par l'IA seule ? | C12: Pas de décision purement automatisée à effet significatif sans humain dans la boucle | D12: Audit features IA → identifier décisions auto à fort impact | E12: 🔴 | F12: 🔁 | H12: ⚠️ RGPD art. 22 + AI Act | I12: 🔧 Audit des features IA 🤖 Claude : identification des décisions automatisées à fort impact
A13: 6.9 | B13: Pouvons-nous reconstituer ce que l'IA a fait pour un utilisateur donné ? | C13: Logs d'inférence IA conservés (audit-trail) : prompt + timestamp + user | D13: Table de logs des prompts/outputs | E13: 🟡 | F13: 🔁 | H13: ⚠️ Anonymisation des prompts sensibles à étudier | I13: 🔧 Helicone (freemium) · audit logs DB
A14: 6.10 | B14: Sait-on précisément quelles données vont vers l'IA et ce qui en revient ? | C14: Documentation interne du flux IA (data lineage) | D14: Diagramme + doc d'architecture IA | E14: 🟢 | F14: 👤 | I14: 🔧 Mermaid / draw.io (gratuit) 🤖 Claude : génération du diagramme de data lineage depuis le code
A15: 6.11 | B15: Un utilisateur peut-il contester une décision prise par l'IA ? | C15: Process documenté pour traiter une plainte sur une décision IA (recours humain) | D15: Endpoint d'appel + email dédié | E15: 🟡 | F15: 👤 | H15: ⚠️ AI Act art. 20 + DSA art. 20 | I15: 🔧 —

Sheet 07_Architecture
A1: 7. Architecture & Scalabilité
A2: Stateless, DB pool, rate-limiter persistent, webhook idempotency, queue, backup, multi-env.
A4: # | B4: Question Chef de Projet | C4: Critère Développeur | D4: Comment tester | E4: Crit. | F4: Auto | G4: Score | H4: Commentaire | I4: Outils & IA
A5: 7.1 | B5: Si on multiplie les serveurs, l'app fonctionne-t-elle toujours ? | C5: Backend stateless (instances interchangeables, pas de session en mémoire) | D5: Tuer une instance pendant une opération → reprise propre ? | E5: 🔴 | F5: 🔁 | I5: 🔧 Tests chaos engineering · Cloud Run / k8s test 🤖 Claude : audit du code pour détecter les états en mémoire
A6: 7.2 | B6: Une montée de charge peut-elle saturer notre base de données ? | C6: Pool de connexions DB borné avec timeout court | D6: Inspecter la config de la couche d'accès aux données | E6: 🔴 | F6: 🤖 | I6: 🔧 Audit config Prisma / Sequelize / SQLAlchemy 🤖 Claude : revue de la config DB pool
A7: 7.3 | B7: Le rate limit fonctionne-t-il même avec plusieurs serveurs en parallèle ? | C7: Rate-limiter persistant (store partagé) si multi-instance | D7: Compteur centralisé ? | E7: 🟡 | F7: 🤖 | I7: 🔧 Redis (gratuit self-host) · Upstash (freemium) 🤖 Claude : audit code rate-limiter
A8: 7.4 | B8: Si Stripe nous envoie deux fois le même événement, on traite deux fois ? | C8: Idempotency sur webhooks externes via table dédiée | D8: Re-jouer le même webhook → pas de double traitement | E8: 🔴 | F8: 🔁 | I8: 🔧 Test manuel via webhook replay · audit code 🤖 Claude : audit des webhook handlers
A9: 7.5 | B9: Les opérations longues bloquent-elles l'utilisateur ou tournent-elles en fond ? | C9: Job queue pour les tâches lourdes (encodage, IA longue, emails masse) | D9: Worker / queue / task system existe | E9: 🟡 | F9: 🤖 | I9: 🔧 Cloud Tasks (GCP) · SQS (AWS) · BullMQ (gratuit)
A10: 7.6 | B10: Les images et JS se chargent-ils vite depuis l'international ? | C10: CDN devant les assets statiques | D10: Cache-Control headers sur /assets/ | E10: 🟢 | F10: 🤖 | I10: 🔧 Cloudflare (gratuit) · Lighthouse (gratuit)
A11: 7.7 | B11: En cas de panne d'un fournisseur, pouvons-nous le diagnostiquer rapidement ? | C11: Health checks sur tous les services externes (DB, stockage, paiement, IA, email) | D11: Endpoint /health retourne le statut de chaque dépendance | E11: 🟡 | F11: 🤖 | I11: 🔧 Audit endpoint /health 🤖 Claude : génération du endpoint health avec checks par dépendance
A12: 7.8 | B12: Pouvons-nous déployer une nouvelle version sans risquer de casser la base ? | C12: Migration DB testée sur staging avant prod, idempotente, réversible | D12: Process de release documenté | E12: 🔴 | F12: 🔁 | H12: ⚠️ Backup avant migration prod obligatoire | I12: 🔧 Prisma Migrate (gratuit) · Flyway (gratuit) 🤖 Claude : revue d'une migration pour identifier les risques (DROP, ALTER non-null)
A13: 7.9 | B13: Avons-nous déjà testé que nos backups marchent vraiment ? | C13: Backup DB automatique + retention ≥ 7 jours + restore testé | D13: Plan DR + dernier test de restore daté | E13: 🔴 | F13: 🔁 | H13: ⚠️ Test de restore réel obligatoire, pas simulable | I13: 🔧 Cloud SQL backups · pgBackRest (gratuit)
A14: 7.10 | B14: Si une zone cloud tombe, l'app reste-t-elle accessible ? | C14: Pas de single point of failure critique (DB répliquée, service critique multi-zones) | D14: Diagramme + plan DR | E14: 🟡 | F14: 👤 | I14: 🔧 Audit architecture 🤖 Claude : revue de l'architecture pour identifier les SPOF
A15: 7.11 | B15: Si on a 10× plus d'utilisateurs demain, l'app tient ? | C15: Capacité à scaler horizontalement (charge × 10 sans refactor) | D15: Test charge ou audit d'archi | E15: 🟡 | F15: 🔁 | I15: 🔧 k6 (gratuit) · Locust (gratuit) · Artillery (gratuit) 🤖 Claude : aide à l'écriture du script de test de charge
A16: 7.12 | B16: Les bases de test sont-elles totalement séparées de la prod ? | C16: Environnements séparés (dev / staging / prod) avec secrets distincts | D16: Variables d'env propres à chaque environnement | E16: 🔴 | F16: 🤖 | I16: 🔧 Audit config CI/CD + secret manager

Sheet 08_Paiement
A1: 8. Paiement & Monétisation
A2: Webhooks, idempotency, dunning, refunds, taxes, facturation, KYC marketplace, métriques.
A4: # | B4: Question Chef de Projet | C4: Critère Développeur | D4: Comment tester | E4: Crit. | F4: Auto | G4: Score | H4: Commentaire | I4: Outils & IA
A5: 8.1 | B5: Stripe nous envoie deux fois le même paiement — l'utilisateur est-il débité deux fois ? | C5: Webhooks paiement avec idempotency stockée (event ID en DB) | D5: Re-jouer un webhook 2× → pas de double traitement | E5: 🔴 | F5: 🔁 | I5: 🔧 Stripe CLI replay (gratuit) 🤖 Claude : audit des handlers webhook
A6: 8.2 | B6: Quelqu'un peut-il nous envoyer un faux paiement pour activer un compte premium ? | C6: Webhooks paiement vérifient la signature du provider | D6: Inspecter le code webhook | E6: 🔴 | F6: 🤖 | I6: 🔧 Audit code 🤖 Claude : vérification que tous les webhooks valident leur signature
A7: 8.3 | B7: Si notre webhook a raté un événement Stripe, l'état se rattrape-t-il automatiquement ? | C7: Subscription / facturation synchronisé DB ↔ provider (cron de réconciliation) | D7: Job de réconciliation existe ? | E7: 🟡 | F7: 🔁 | I7: 🔧 Cron job custom · revue code 🤖 Claude : aide à écrire le job de réconciliation
A8: 8.4 | B8: Quand un paiement échoue, que se passe-t-il pour l'utilisateur ? | C8: Past-due / dunning : grace period documentée puis blocage features payantes | D8: Tester invoice failed → comportement attendu | E8: 🟡 | F8: 🔁 | I8: 🔧 Stripe test mode · test manuel
A9: 8.5 | B9: Un utilisateur insatisfait sait-il comment se faire rembourser ? | C9: Process refund documenté (conditions, délai, qui peut le faire) | D9: Self-service ou support clair | E9: 🟡 | F9: 👤 | I9: 🔧 — 🤖 Claude : rédaction de la politique de remboursement et FAQ associée
A10: 8.6 | B10: Facturons-nous la bonne TVA selon le pays de l'acheteur ? | C10: Taxes (TVA, sales tax) calculées correctement selon pays acheteur | D10: Test commande dans 3 juridictions | E10: 🔴 | F10: 🤖 | H10: ⚠️ Validation comptable obligatoire | I10: 🔧 Stripe Tax (payant) · TaxJar · Lemon Squeezy (merchant of record)
A11: 8.7 | B11: Le prix affiché correspond-il bien à ce que l'utilisateur paiera vraiment ? | C11: Affichage TTC / HT explicite sur la page pricing selon obligations locales | D11: Audit visuel page pricing | E11: 🔴 | F11: 🔁 | H11: ⚠️ Législation française : TTC obligatoire B2C | I11: 🔧 Audit visuel + revue code pricing
A12: 8.8 | B12: Vérifions-nous l'identité avant de verser de l'argent à un vendeur ? | C12: Marketplace / payouts : KYC validé avant tout versement, AML conforme | D12: Payout impossible si KYC pending | E12: 🟡 | F12: 🔁 | I12: 🔧 Stripe Connect Express (inclus) · Onfido (payant) 🤖 Claude : audit du flow de payout pour vérifier le KYC gate
A13: 8.9 | B13: L'utilisateur reçoit-il une vraie facture PDF pour sa comptabilité ? | C13: Facturation automatique (PDF) + archivage selon obligations comptables | D13: Facture envoyée + accessible dans le compte | E13: 🔴 | F13: 🤖 | H13: ⚠️ Archivage 10 ans en France | I13: 🔧 Stripe Invoicing (inclus) · Sellsy / Pennylane (payant)
A14: 8.10 | B14: Sait-on en un coup d'œil comment va le business ? | C14: Dashboard MRR / churn / LTV / cohortes pour le founder | D14: Dashboard analytics produit existe ? | E14: 🟢 | F14: 🔁 | I14: 🔧 ChartMogul (payant) · ProfitWell / Paddle (freemium) · dashboard custom 🤖 Claude : aide à la requête SQL pour MRR / cohortes
A15: 8.11 | B15: L'utilisateur sait-il quand son essai se termine et ce qui se passera ? | C15: Gestion des essais (trial) : conversion automatique ou manuelle annoncée | D15: Tester fin de trial → comportement et notif | E15: 🟡 | F15: 🔁 | I15: 🔧 Stripe test mode · Playwright
A16: 8.12 | B16: Si un utilisateur change de plan en milieu de mois, le calcul est-il transparent ? | C16: Politique de proration claire en cas d'upgrade / downgrade en milieu de cycle | D16: Tester upgrade Pro → Business → calcul cohérent | E16: 🟡 | F16: 🔁 | I16: 🔧 Stripe proration test mode

Sheet 09_Observabilite
A1: 9. Observabilité & Ops
A2: Logs structurés, alertes, uptime, runbook, rollback, métriques business.
A4: # | B4: Question Chef de Projet | C4: Critère Développeur | D4: Comment tester | E4: Crit. | F4: Auto | G4: Score | H4: Commentaire | I4: Outils & IA
A5: 9.1 | B5: Quand un bug arrive en prod, peut-on tracer ce qui s'est passé en quelques minutes ? | C5: Logs structurés (JSON) avec severity et requestId/traceId | D5: Logs prod exploitables par filtre ? | E5: 🟡 | F5: 🔁 | I5: 🔧 Cloud Logging (inclus) · Datadog (payant) · Pino/Winston (gratuit) 🤖 Claude : refactor de console.log vers logger structuré
A6: 9.2 | B6: Nos logs contiennent-ils des données personnelles à risque ? | C6: Aucune PII dans les logs (email, mot de passe, CB, token) | D6: grep sur les logs des 24h passées | E6: 🔴 | F6: 🤖 | I6: 🔧 grep avec patterns PII · Datadog Sensitive Data Scanner (payant) 🤖 Claude : audit des points de logging dans le code pour détecter les leaks PII
A7: 9.3 | B7: Sommes-nous prévenus avant les utilisateurs quand quelque chose plante ? | C7: Alertes automatiques sur erreurs 5xx > seuil | D7: Alerte configurée et testée | E7: 🔴 | F7: 🤖 | I7: 🔧 Sentry (freemium) · Cloud Monitoring · Datadog (payant)
A8: 9.4 | B8: Si nos coûts cloud explosent, on est prévenus avant la facture ? | C8: Alerte budget (cloud, paiement, IA) en cas de dépassement | D8: Configuration vérifiée | E8: 🟡 | F8: 🤖 | I8: 🔧 GCP / AWS / Azure Billing Alerts (gratuit)
A9: 9.5 | B9: Si tout notre cloud tombe, sommes-nous quand même prévenus depuis l'extérieur ? | C9: Uptime monitoring externe (indépendant du cloud du SaaS) | D9: Couper le service → alerte arrive < 5 min | E9: 🟡 | F9: 🤖 | I9: 🔧 UptimeRobot (freemium) · BetterStack (freemium) · Pingdom (payant)
A10: 9.6 | B10: En cas d'incident grave à 3h du matin, sait-on quoi faire ? | C10: Playbook incident documenté (qui appeler, comment rollback, communication client) | D10: Document RUNBOOK.md ou équivalent | E10: 🟡 | F10: 👤 | H10: ⚠️ Validation par l'équipe astreinte | I10: 🔧 Notion / GitHub wiki 🤖 Claude : rédaction du runbook depuis une description de l'archi
A11: 9.7 | B11: Nos clients peuvent-ils vérifier eux-mêmes si nos services tournent ? | C11: Status page publique pour les incidents | D11: URL accessible publiquement | E11: 🟢 | F11: 🤖 | I11: 🔧 Instatus (freemium) · BetterStack (freemium) · Statuspage Atlassian (payant)
A12: 9.8 | B12: Connaissons-nous les temps de réponse réels de nos endpoints critiques ? | C12: Métrique de latence p50/p95/p99 sur les endpoints critiques | D12: Tracing distribué ou métriques applicatives | E12: 🟢 | F12: 🤖 | I12: 🔧 OpenTelemetry (gratuit) · Datadog APM (payant)
A13: 9.9 | B13: Si une mise en prod plante, peut-on revenir à la version précédente très vite ? | C13: Capacité à rollback en < 5 min sur production | D13: Versions précédentes accessibles + process documenté | E13: 🔴 | F13: 🤖 | I13: 🔧 Cloud Run revisions · k8s rollback · Vercel rollback
A14: 9.10 | B14: Les utilisateurs voient-ils ce qu'on a livré récemment ? | C14: Changelog visible utilisateurs (release notes) | D14: URL /changelog ou widget 'Quoi de neuf' | E14: 🟢 | F14: 🤖 | I14: 🔧 Conventional Commits + semantic-release (gratuit) · Beamer / Headway (payant) 🤖 Claude : reformulation du changelog technique en notes business
A15: 9.11 | B15: Voit-on les erreurs JavaScript qui arrivent sur le navigateur des utilisateurs ? | C15: Process de gestion des erreurs côté client (Sentry / Rollbar) | D15: Tableau de bord des erreurs JS en prod | E15: 🟡 | F15: 🤖 | I15: 🔧 Sentry (freemium) · Rollbar (freemium) · Bugsnag (freemium)
A16: 9.12 | B16: Sait-on combien d'inscriptions et de conversions on a fait cette semaine ? | C16: Métriques business clés (signup, conversion, activation) instrumentées | D16: Dashboard avec ces 3 chiffres au moins | E16: 🟡 | F16: 🤖 | I16: 🔧 PostHog (freemium) · Mixpanel (freemium) · Amplitude (freemium)

Sheet 10_Legal
A1: 10. Légal & Conformité
A2: CGU/CGV, Privacy, mentions, médiation, cookies, rétractation, hébergeur, accessibilité.
A4: # | B4: Question Chef de Projet | C4: Critère Développeur | D4: Comment tester | E4: Crit. | F4: Auto | G4: Score | H4: Commentaire | I4: Outils & IA
A5: 10.1 | B5: L'acceptation des CGU est-elle explicite et tracée ? | C5: Conditions d'utilisation acceptées explicitement à l'inscription (checkbox non pré-cochée) | D5: Tester signup → blocage si non cochée | E5: 🔴 | F5: 🔁 | I5: 🔧 Playwright signup test (gratuit)
A6: 10.2 | B6: L'utilisateur peut-il consulter les CGV avant de payer ? | C6: Conditions de vente disponibles avant le paiement (lien visible) | D6: Audit du flow checkout | E6: 🔴 | F6: 🔁 | I6: 🔧 Audit visuel checkout
A7: 10.3 | B7: Le lien vers la politique de confidentialité est-il visible partout ? | C7: Politique de confidentialité accessible depuis chaque page | D7: Lien dans le footer présent partout | E7: 🔴 | F7: 🤖 | I7: 🔧 grep sur le footer + audit pages
A8: 10.4 | B8: Nos mentions légales sont-elles complètes et à jour ? | C8: Mentions / informations légales obligatoires selon juridiction | D8: Audit mentions légales | E8: 🔴 | F8: 👤 | H8: ⚠️ Validation juridique obligatoire | I8: 🔧 Modèle CNIL · validation juridique 🤖 Claude : génération d'une première version à partir des infos société
A9: 10.5 | B9: Avons-nous désigné un médiateur de la consommation (loi française B2C) ? | C9: Médiateur / mécanisme de résolution des litiges si juridiction l'impose B2C | D9: Mentions légales — coordonnées + URL | E9: 🟡 | F9: 👤 | H9: ⚠️ Obligation française L. 612-1 du Code de la consommation | I9: 🔧 —
A10: 10.6 | B10: L'utilisateur connaît-il son droit de rétractation 14 jours (UE B2C) ? | C10: Droit de rétractation / cooling-off documenté si requis | D10: CGV — clause présente ? | E10: 🟡 | F10: 👤 | I10: 🔧 — 🤖 Claude : rédaction de la clause selon juridiction
A11: 10.7 | B11: Avons-nous un mécanisme de signalement de contenu illégal ? | C11: Hébergement de contenu user : régime de responsabilité + procédure de notification/retrait | D11: Endpoint de signalement | E11: 🟡 | F11: 🔁 | H11: ⚠️ LCEN art. 6 + DSA art. 16 | I11: 🔧 Audit endpoint /report
A12: 10.8 | B12: L'utilisateur peut-il choisir cookie par cookie ce qu'il accepte ? | C12: Cookies 'non essentiels' listés avec finalité et refus catégoriel | D12: Bannière de cookies — détail par catégorie | E12: 🔴 | F12: 🤖 | I12: 🔧 Axeptio · Cookiebot · Klaro
A13: 10.9 | B13: Si un utilisateur demande l'accès à ses données, lui répond-on en temps légal ? | C13: Email de contact officiel répondant en délai imposé (UE RGPD : 30 jours) | D13: Test : envoyer demande sur email officiel | E13: 🟡 | F13: 👤 | I13: 🔧 —
A14: 10.10 | B14: Pouvons-nous prouver à quel moment chaque utilisateur a accepté nos CGU ? | C14: Stockage durable des CGU acceptées (timestamp + version) par utilisateur | D14: Champ acceptedTermsAt + version en DB | E14: 🟡 | F14: 🔁 | I14: 🔧 Audit schema DB
A15: 10.11 | B15: Si on suspend un compte, l'utilisateur peut-il faire appel ? | C15: Process d'appel / recours si suspension de compte ou retrait de contenu | D15: Endpoint d'appel ou email dédié | E15: 🟡 | F15: 🔁 | H15: ⚠️ DSA art. 20 | I15: 🔧 Audit endpoint /appeals
A16: 10.12 | B16: Notre site est-il accessible aux personnes en situation de handicap ? | C16: Accessibilité web (WCAG AA si service public en UE ; ADA US) | D16: Lighthouse a11y audit ≥ 90 | E16: 🟡 | F16: 🔁 | H16: ⚠️ Tests avec utilisateurs en situation de handicap recommandés | I16: 🔧 Lighthouse (gratuit) · axe DevTools (gratuit) · WAVE (gratuit) 🤖 Claude : audit du HTML/JSX pour identifier les problèmes WCAG non automatisables
A17: 10.13 | B17: Mentionnons-nous explicitement l'usage d'IA dans nos documents légaux ? | C17: Mention du recours aux outils IA dans la politique de confidentialité et CGU | D17: Section dédiée présente | E17: 🔴 | F17: 👤 | I17: 🔧 — 🤖 Claude : rédaction de la section IA des CGU/Privacy

Sheet 11_UX_UI_Design
A1: 11. UX/UI — Qualité de design
A2: Design system, palette, typo, spacing, états visuels, animations, branding, responsive.
A4: # | B4: Question Chef de Projet | C4: Critère Développeur | D4: Comment tester | E4: Crit. | F4: Auto | G4: Score | H4: Commentaire | I4: Outils & IA
A5: 11.1 | B5: Avons-nous un système de design unifié ou chaque page est-elle différente ? | C5: Design system documenté (couleurs, typo, spacing, composants) avec règles d'usage | D5: Storybook / Figma library / tokens.css partagé | E5: 🟡 | F5: 🔁 | I5: 🔧 Storybook (gratuit) · Figma (freemium) 🤖 Claude : audit de la cohérence des composants depuis le code
A6: 11.2 | B6: Nos couleurs offrent-elles un contraste suffisant pour la lisibilité ? | C6: Palette de couleurs avec contraste WCAG AA validé sur tous les usages | D6: Audit avec contrast-checker sur les combinaisons utilisées | E6: 🟡 | F6: 🤖 | I6: 🔧 WebAIM Contrast Checker · Lighthouse (gratuit)
A7: 11.3 | B7: Nos polices sont-elles hébergées chez nous ou dépendent-elles d'un tiers ? | C7: Hiérarchie typo claire (max 3-4 niveaux), polices self-hosted (pas SPOF CDN tiers) | D7: Inspecter font-family + Network | E7: 🟡 | F7: 🤖 | I7: 🔧 DevTools Network · Fontsource (self-host gratuit)
A8: 11.4 | B8: Nos écrans donnent-ils une impression de rigueur et d'organisation ? | C8: Spacing / grid system cohérent (échelle 4/8/16/24/32) | D8: Audit visuel — éléments alignés sur une grille ? | E8: 🟢 | F8: 🔁 | I8: 🔧 Storybook · audit Figma 🤖 Claude : audit des classes Tailwind / CSS pour détecter les espacements ad-hoc
A9: 11.5 | B9: Combien de boutons différents avons-nous ? (Idéal : 3-5 max) | C9: Composants UI réutilisables (boutons, inputs, modales) — pas N variations ad-hoc | D9: grep ou Storybook : combien de Button différents ? | E9: 🟡 | F9: 🤖 | I9: 🔧 grep <button + variants 🤖 Claude : recensement des variantes de composants et propositions de factorisation
A10: 11.6 | B10: Tous nos boutons et champs ont-ils des états visuels pour chaque interaction ? | C10: États visuels couverts pour chaque composant interactif (default/hover/focus/active/disabled/loading/error) | D10: Interagir avec chaque composant via souris ET clavier | E10: 🟡 | F10: 🔁 | I10: 🔧 Storybook (gratuit) 🤖 Claude : audit du code des composants pour vérifier les états
A11: 11.7 | B11: Voit-on où le clavier est dans la page quand on navigue sans souris ? | C11: Focus rings visibles (accessibilité clavier) sans être intrusifs | D11: Tab à travers la page sur fond clair ET sombre | E11: 🟡 | F11: 🔁 | I11: 🔧 axe DevTools · test clavier manuel
A12: 11.8 | B12: Les boutons sur mobile sont-ils assez grands pour le pouce ? | C12: Touch targets ≥ 44×44 px sur mobile (reco Apple/Google) | D12: DevTools mobile + mesurer les zones tappables | E12: 🟡 | F12: 🤖 | I12: 🔧 Lighthouse a11y · audit CSS
A13: 11.9 | B13: Nos animations sont-elles désactivables pour les utilisateurs sensibles au mouvement ? | C13: Animations purposeful (≤ 300ms) + respect de prefers-reduced-motion | D13: Activer prefers-reduced-motion → animations stoppées ? | E13: 🟢 | F13: 🤖 | I13: 🔧 DevTools rendering · audit CSS 🤖 Claude : grep des @media (prefers-reduced-motion)
A14: 11.10 | B14: Quand une liste est vide, l'utilisateur sait-il quoi faire ? | C14: Empty states designés (pas un blanc) — chaque liste vide a un message + action | D14: Tester chaque liste/tableau à vide | E14: 🟡 | F14: 🔁 | I14: 🔧 Audit visuel manuel · Storybook 🤖 Claude : audit des composants liste pour vérifier le rendu empty
A15: 11.11 | B15: Quand quelque chose plante, l'utilisateur sait-il comment réagir ? | C15: Error states informatifs (qu'est-ce qui s'est passé, comment corriger) | D15: Provoquer chaque erreur — message actionable ? | E15: 🟡 | F15: 🔁 | I15: 🔧 Playwright route mocking 🤖 Claude : audit des messages d'erreur pour clarté et actionnabilité
A16: 11.12 | B16: Voit-on toujours quelque chose pendant les chargements ? | C16: Loading states adaptés (skeletons pour listes, spinners pour actions, progress pour upload) | D16: Throttler le réseau → feedback visuel cohérent | E16: 🟢 | F16: 🔁 | I16: 🔧 DevTools throttling
... A22: 11.18 | B22: Nos notifications sont-elles cohérentes et non bloquantes ? | C22: Notifications (toasts) cohérents : positionnement fixe, durée standardisée, dismissable | D22: Déclencher plusieurs toasts en parallèle | E22: 🟡 | F22: 🔁 | I22: 🔧 Audit visuel · Storybook
A23: 11.19 | B23: Notre app respecte-t-elle l'éthique du design ou utilise-t-elle des manipulations ? | C23: Pas de dark patterns (croix introuvable, urgence factice, opt-in pré-coché, désabonnement caché) | D23: Audit éthique — un tiers neutre repère-t-il un pattern manipulatoire ? | E23: 🔴 | F23: 👤 | H23: ⚠️ Décision éthique humaine | I23: 🔧 deceptive.design (gratuit, référentiel) 🤖 Claude : audit des patterns d'UI pour identifier les dark patterns connus
A24: 11.20 | B24: Quand on revient en arrière, retrouve-t-on l'état où on l'avait laissé ? | C24: Cohérence multi-écrans : revenir à un écran préserve l'état (scroll, filtres, sélection) | D24: Tester nav avant/arrière dans le navigateur | E24: 🟢 | F24: 🔁 | I24: 🔧 Playwright navigation tests

Sheet 12_Frontend_Backend
A1: 12. Frontend ↔ Backend
A2: Contrats API, HTTP semantique, naming/dates/pagination, validation, cache, versioning, CORS, idempotency.
A4: # | B4: Question Chef de Projet | C4: Critère Développeur | D4: Comment tester | E4: Crit. | F4: Auto | G4: Score | H4: Commentaire | I4: Outils & IA
A5: 12.1 | B5: Quand l'API change, le frontend casse-t-il à la compilation ou seulement en runtime ? | C5: Types partagés frontend ↔ backend (OpenAPI, GraphQL, Zod monorepo, tRPC…) | D5: Changer un champ backend → erreur TS côté frontend ? | E5: 🟡 | F5: 🤖 | I5: 🔧 OpenAPI Generator (gratuit) · tRPC (gratuit) · GraphQL Codegen (gratuit) 🤖 Claude : génération de la couche de types depuis OpenAPI
A6: 12.2 | B6: Tous nos endpoints retournent-ils les erreurs dans le même format ? | C6: Format d'erreur API uniforme partout ({ error, code?, fields? } ou équivalent) | D6: Inspecter 10 endpoints en erreur → même structure ? | E6: 🔴 | F6: 🤖 | I6: 🔧 Postman / Hoppscotch · revue code middleware d'erreur 🤖 Claude : audit des handlers d'erreur pour uniformiser
A7: 12.3 | B7: Les codes HTTP renvoyés respectent-ils la sémantique standard ? | C7: HTTP status codes sémantiquement corrects (201/204/400/401/403/404/422/429/5xx) | D7: Tester chaque cas → bon code retourné ? | E7: 🟡 | F7: 🤖 | I7: 🔧 Tests API automatisés · Schemathesis (gratuit) 🤖 Claude : audit route par route des codes retournés
A8: 12.4 | B8: Nos endpoints respectent-ils la convention REST ? | C8: Verbes HTTP respectés (GET idempotent, POST create, PUT replace, PATCH partial, DELETE) | D8: Audit route par route | E8: 🟡 | F8: 🤖 | I8: 🔧 grep app.get|app.post + revue code 🤖 Claude : audit sémantique des routes
A9: 12.5 | B9: Nos APIs renvoient-elles les champs avec une convention de nommage uniforme ? | C9: Naming des champs cohérent (camelCase OU snake_case partout, pas mélangé) | D9: Inspecter 10 endpoints + frontend usage | E9: 🟡 | F9: 🤖 | I9: 🔧 grep + ESLint rule custom 🤖 Claude : audit du naming et propositions de refactor
A10: 12.6 | B10: Les dates renvoyées par l'API sont-elles toutes au même format ? | C10: Format de dates uniforme (ISO 8601 dans les réponses, parsing identique côté frontend) | D10: Audit des champs *At / *Date | E10: 🟡 | F10: 🤖 | I10: 🔧 grep des champs date · tests d'intégration
A11: 12.7 | B11: Notre pagination est-elle cohérente sur tous les endpoints qui retournent des listes ? | C11: Pagination uniforme (offset/limit OU cursor partout) | D11: Inspecter 3-5 endpoints paginés | E11: 🟡 | F11: 🤖 | I11: 🔧 Audit code des endpoints liste 🤖 Claude : audit des endpoints paginés pour uniformiser
A12: 12.8 | B12: Les règles de saisie sont-elles cohérentes entre l'UI et le serveur ? | C12: Validation frontend mirror exactement la validation backend (min/max/regex/format) | D12: Bypass frontend → erreur backend ≡ erreur frontend ? | E12: 🟡 | F12: 🔁 | I12: 🔧 Test manuel · Zod schemas partagés (gratuit) 🤖 Claude : audit des schemas de validation frontend vs backend
A13: 12.9 | B13: Un utilisateur sans droits voit-il quand même des boutons qui ne marcheront pas ? | C13: Frontend cache features non autorisées (mais backend re-vérifie quand même) | D13: Token avec rôle limité → UI adaptée ET endpoint refuse | E13: 🟡 | F13: 🔁 | I13: 🔧 Test manuel multi-rôle
A14: 12.10 | B14: Si une action échoue après affichage optimiste, l'UI revient-elle en arrière proprement ? | C14: Optimistic UI avec rollback sur erreur (si utilisé) — pas de flash puis revert silencieux | D14: Couper le réseau pendant une action optimiste → revert ? | E14: 🟢 | F14: 🔁 | I14: 🔧 Playwright route mocking (gratuit)
A15: 12.11 | B15: Après modification, la liste se met-elle à jour automatiquement ? | C15: Cache invalidation après mutation (refresh la query React Query/SWR) | D15: Modifier une ressource → liste se rafraîchit sans reload ? | E15: 🟡 | F15: 🔁 | I15: 🔧 Test manuel · audit code React Query / SWR 🤖 Claude : audit des mutations React Query pour vérifier l'invalidation
A16: 12.12 | B16: Si la connexion temps réel se coupe, se reconnecte-t-elle automatiquement ? | C16: WebSocket / SSE / polling : reconnexion automatique, état UI synchronisé | D16: Couper le wifi 30s puis rétablir → état cohérent ? | E16: 🟢 | F16: 🔁 | I16: 🔧 Test manuel · DevTools network throttling
... A28: 12.24 | B28: Quand le réseau coupe, l'app retente intelligemment ou abandonne brutalement ? | C28: Erreurs réseau gérées proprement côté frontend (retry exponentiel sur 5xx, abandon clair sur 4xx) | D28: Couper le réseau → comportement attendu | E28: 🟡 | F28: 🔁 | I28: 🔧 Playwright route mocking · audit code retry 🤖 Claude : audit des fetch wrappers pour stratégie de retry

Sheet 13_Documentation_Maintenance
A1: 13. Documentation & Maintenance
A2: Doc technique, doc utilisateur/admin, versioning, qualité du code, dette technique.
A4: # | B4: Question Chef de Projet | C4: Critère Développeur | D4: Comment tester | E4: Crit. | F4: Auto | G4: Score | H4: Commentaire | I4: Outils & IA
A5: 13.1 | B5: Un nouveau développeur peut-il faire tourner le projet sans aide orale ? | C5: README à jour avec instructions d'installation et de démarrage | D5: Cloner le repo + suivre le README → projet tourne ? | E5: 🟡 | F5: 🔁 | I5: 🔧 Audit visuel + test sur machine vierge 🤖 Claude : rédaction du README à partir d'une lecture du code
